<?xml version="1.0" ?>
<!-- =================================================================================== -->
<!-- |    This document was autogenerated by xacro from sample.urdf.xacro              | -->
<!-- |    EDITING THIS FILE BY HAND IS NOT RECOMMENDED                                 | -->
<!-- =================================================================================== -->
<!-- top of urdf -->
<robot name="sample_robot" xmlns:xacro="http://ros.org/wiki/xacro">
  <!-- defined num and set of link and joint -->
  <!-- lowest level of xacro -->
  <!-- valiables to be used -->
  <!-- link to provide the location reference for the arm -->
  <link name="base_link"/>
  <!-- 1. the first top link and joint -->
  <link name="sample_robot_mounting_link"/>
  <joint name="sample_robot_mounting_joint" type="fixed">
    <origin xyz="0 0 0"/>
    <parent link="base_link"/>
    <child link="sample_robot_mounting_link"/>
  </joint>
  <joint name="mounting_bracket_a_joint" type="fixed">
    <origin rpy="0 0 0" xyz="0 0 0"/>
    <parent link="sample_robot_mounting_link"/>
    <child link="mounting_bracket_a_link"/>
  </joint>
  <link name="mounting_bracket_a_link">
    <visual>
      <origin rpy="0 0 0" xyz="0 0 0.0255"/>
      <geometry>
        <cylinder length="0.051" radius="0.056"/>
      </geometry>
    </visual>
    <!-- FIXME add collision and inetia -->
  </link>
  <!-- FIXME add llimit ulimit vlimit -->
  <joint name="mounting_bracket_b_joint" type="continuous">
    <origin rpy="0 0 0" xyz="0 0 0.051"/>
    <axis xyz="0 0 1"/>
    <parent link="mounting_bracket_a_link"/>
    <child link="mounting_bracket_b_link"/>
  </joint>
  <link name="mounting_bracket_b_link">
    <visual>
      <!-- FIXME change this to stl -->
      <origin rpy="0 0 0" xyz="0 0 0.0255"/>
      <geometry>
        <cylinder length="0.051" radius="0.056"/>
      </geometry>
      <!-- add collision and inertial -->
    </visual>
  </link>
  <joint name="motor_cover_1_a_joint" type="fixed">
    <origin rpy="0 0 0" xyz="0 0 0.051"/>
    <parent link="mounting_bracket_b_link"/>
    <child link="motor_cover_1_a_link"/>
  </joint>
  <link name="motor_cover_1_a_link">
    <!-- FIXME add inertial and collision -->
    <visual>
      <origin rpy="0 0 0" xyz="0.0325 0 0.0545"/>
      <geometry>
        <box size="0.065 0.075 0.109"/>
      </geometry>
    </visual>
  </link>
  <!-- FIXME add limit and ulimit vilimit-->
  <joint name="motor_cover_1_b_joint" type="continuous">
    <origin rpy="0 0 0" xyz="0 0 0.0615"/>
    <parent link="motor_cover_1_a_link"/>
    <child link="motor_cover_1_b_link"/>
  </joint>
  <link name="motor_cover_1_b_link">
    <visual>
      <origin rpy="0 0 0" xyz="-0.032 0 0"/>
      <geometry>
        <box size="0.064 0.075 0.109"/>
      </geometry>
    </visual>
  </link>
</robot>
