<?xml version="1.0" ?>
<!-- =================================================================================== -->
<!-- |    This document was autogenerated by xacro from sample.urdf.xacro              | -->
<!-- |    EDITING THIS FILE BY HAND IS NOT RECOMMENDED                                 | -->
<!-- =================================================================================== -->
<!-- top of urdf -->
<robot name="sample_robot" xmlns:xacro="http://ros.org/wiki/xacro">
  <!-- defined num and set of link and joint -->
  <!-- lowest level of xacro -->
  <!-- valiables to be used -->
  <!-- link to provide the location reference for the arm -->
  <link name="base_link"/>
  <!-- 1. the first top link and joint -->
  <link name="sample_robot_mounting_link"/>
  <joint name="sample_robot_mounting_joint" type="fixed">
    <origin xyz="0 0 0"/>
    <parent link="base_link"/>
    <child link="sample_robot_mounting_link"/>
  </joint>
  <joint name="bracket_0_1_joint" type="fixed">
    <origin rpy="0 0 0" xyz="0 0 0"/>
    <parent link="sample_robot_mounting_link"/>
    <child link="bracket_1_link"/>
  </joint>
  <link name="bracket_1_link">
    <visual>
      <origin rpy="0 0 0" xyz="0 0 0.0255"/>
      <geometry>
        <cylinder length="0.051" radius="0.056"/>
      </geometry>
    </visual>
    <!-- FIXME add collision and inetia -->
  </link>
  <!-- FIXME add llimit ulimit vlimit -->
  <joint name="bracket_1_2_joint" type="continuous">
    <origin rpy="0 0 0" xyz="0 0 0.051"/>
    <axis xyz="0 0 1"/>
    <parent link="bracket_1_link"/>
    <child link="bracket_2_link"/>
  </joint>
  <link name="bracket_2_link">
    <visual>
      <!-- FIXME change this to stl -->
      <origin rpy="0 0 0" xyz="0 0 0"/>
      <geometry>
        <box size="0.065 0.075 0.160"/>
      </geometry>
      <!-- add collision and inertial -->
    </visual>
  </link>
  <!-- FIXME add limit and ulimit vilimit -->
  <joint name="brackt_2_3_joint" type="continuous">
    <origin rpy="0 0 0" xyz="0 0 0.1125"/>
    <parent link="bracket_2_link"/>
    <child link="bracket_3_link"/>
  </joint>
  <link name="bracket_3_link">
    <visual>
      <origin rpy="0 0 0" xyz="0 0 0"/>
      <geometry>
        <box size="0.064 0.075 0.154"/>
      </geometry>
    </visual>
  </link>
  <!-- add color and limis -->
  <joint name="bracket_3_4_joint" type="continuous">
    <origin rpy="0 0 0" xyz="0 0 0.1065"/>
    <axis xyz="0 0 1"/>
    <parent link="bracket_3_link"/>
    <child link="bracket_4_link"/>
  </joint>
  <link name="bracket_4_link">
    <!-- add collision -->
    <visual>
      <origin rpy="0 0 0" xyz="0 0 0.022"/>
      <geometry>
        <cylinder length="0.044" radius="0.0475"/>
      </geometry>
    </visual>
  </link>
  <joint name="bracket_4_5_joint" type="continuous">
    <origin rpy="0 0 0" xyz="0 0 0.1055"/>
    <parent link="bracket_4_link"/>
    <child link="bracket_5_link"/>
  </joint>
  <link name="bracket_5_link">
    <!-- add collision and so on -->
    <visual>
      <origin rpy="0 0 0" xyz="-0.032 0 0.0365"/>
      <geometry>
        <box size="0.064 0.093 0.196"/>
      </geometry>
    </visual>
  </link>
  <joint name="bracket_5_6_joint" type="continuous">
    <origin rpy="0 0 0" xyz="0 0 0.098"/>
    <parent link="bracket_5_link"/>
    <child link="bracket_6_link"/>
  </joint>
  <link name="bracket_6_link">
    <visual>
      <origin rpy="0 0 0" xyz="0 0 0"/>
      <geometry>
        <box size="0.051 0.093 0.138"/>
      </geometry>
    </visual>
  </link>
  <joint name="end_effector_joint" type="continuous">
    <origin rpy="0 0 0" xyz="0 0 0.0915"/>
    <axis xyz="0 0 1"/>
    <parent link="bracket_6_link"/>
    <child link="end_effector_link"/>
  </joint>
  <link name="end_effector_link">
    <visual>
      <origin rpy="0 0 0" xyz="0 0 0"/>
      <geometry>
        <box size="0.093 0.093 0.031"/>
      </geometry>
    </visual>
  </link>
</robot>
