<?xml version="1.0" ?>
<!-- =================================================================================== -->
<!-- |    This document was autogenerated by xacro from sample.urdf.xacro              | -->
<!-- |    EDITING THIS FILE BY HAND IS NOT RECOMMENDED                                 | -->
<!-- =================================================================================== -->
<!-- top of urdf -->
<robot name="sample_robot" xmlns:xacro="http://ros.org/wiki/xacro">
  <!-- defined num and set of link and joint -->
  <!-- lowest level of xacro -->
  <!-- valiables to be used -->
  <material name="black">
    <color rgba="0.2 0.2 0.2 1.0"/>
  </material>
  <!-- link to provide the location reference for the arm -->
  <link name="base_link"/>
  <!-- 1. the first top link and joint -->
  <link name="sample_robot_mounting_link"/>
  <joint name="sample_robot_mounting_joint" type="fixed">
    <origin xyz="0 0 0"/>
    <parent link="base_link"/>
    <child link="sample_robot_mounting_link"/>
  </joint>
  <joint name="bracket_0_1_joint" type="fixed">
    <origin rpy="0 0 0" xyz="0 0 0"/>
    <parent link="sample_robot_mounting_link"/>
    <child link="bracket_1_link"/>
  </joint>
  <link name="bracket_1_link">
    <visual>
      <origin rpy="0 -1.57079632679 0" xyz="0 0 0"/>
      <geometry>
        <mesh filename="package://my_robot_description/meshes/bracket_1_simple.stl" scale="0.001 0.001 0.001"/>
      </geometry>
      <material name="black"/>
    </visual>
    <!-- FIXME add collision and inetia -->
  </link>
  <!-- FIXME add llimit ulimit vlimit -->
  <joint name="bracket_1_2_joint" type="continuous">
    <origin rpy="0 0 0" xyz="0 0 0.051"/>
    <axis xyz="0 0 1"/>
    <parent link="bracket_1_link"/>
    <child link="bracket_2_link"/>
  </joint>
  <link name="bracket_2_link">
    <visual>
      <!-- FIXME change this to stl -->
      <origin rpy="0 0 0" xyz="0 0 0"/>
      <geometry>
        <mesh filename="package://my_robot_description/meshes/bracket_2.stl" scale="0.001 0.001 0.001"/>
      </geometry>
      <!-- add collision and inertial -->
    </visual>
  </link>
  <!-- FIXME add limit and ulimit vilimit -->
  <joint name="brackt_2_3_joint" type="continuous">
    <origin rpy="0 0 0" xyz="0 0 0.1125"/>
    <parent link="bracket_2_link"/>
    <child link="bracket_3_link"/>
  </joint>
  <link name="bracket_3_link">
    <visual>
      <origin rpy="0 0 0" xyz="0 0 0"/>
      <geometry>
        <mesh filename="package://my_robot_description/meshes/bracket_3.stl" scale="0.001 0.001 0.001"/>
      </geometry>
    </visual>
  </link>
  <!-- add color and limis -->
  <joint name="bracket_3_4_joint" type="continuous">
    <origin rpy="0 0 0" xyz="0 0 0.1065"/>
    <axis xyz="0 0 1"/>
    <parent link="bracket_3_link"/>
    <child link="bracket_4_link"/>
  </joint>
  <link name="bracket_4_link">
    <!-- add collision -->
    <visual>
      <origin rpy="0 0 0" xyz="0 0 0"/>
      <geometry>
        <mesh filename="package://my_robot_description/meshes/bracket_4.stl" scale="0.001 0.001 0.001"/>
      </geometry>
    </visual>
  </link>
  <joint name="bracket_4_5_joint" type="continuous">
    <origin rpy="0 0 0" xyz="0 0 0.1055"/>
    <parent link="bracket_4_link"/>
    <child link="bracket_5_link"/>
  </joint>
  <link name="bracket_5_link">
    <!-- add collision and so on -->
    <visual>
      <origin rpy="0 0 0" xyz="0 0 0"/>
      <geometry>
        <mesh filename="package://my_robot_description/meshes/bracket_5.stl" scale="0.001 0.001 0.001"/>
      </geometry>
    </visual>
  </link>
  <joint name="bracket_5_6_joint" type="continuous">
    <origin rpy="0 0 0" xyz="0 0 0.098"/>
    <parent link="bracket_5_link"/>
    <child link="bracket_6_link"/>
  </joint>
  <link name="bracket_6_link">
    <visual>
      <origin rpy="0 0 0" xyz="0 0 0"/>
      <geometry>
        <mesh filename="package://my_robot_description/meshes/bracket_6.stl" scale="0.001 0.001 0.001"/>
      </geometry>
    </visual>
  </link>
  <joint name="end_effector_joint" type="continuous">
    <origin rpy="0 0 0" xyz="0 0 0.0915"/>
    <axis xyz="0 0 1"/>
    <parent link="bracket_6_link"/>
    <child link="end_effector_link"/>
  </joint>
  <link name="end_effector_link">
    <visual>
      <origin rpy="0 0 0" xyz="0 0 0"/>
      <geometry>
        <mesh filename="package://my_robot_description/meshes/bracket_7.stl" scale="0.001 0.001 0.001"/>
      </geometry>
    </visual>
  </link>
</robot>

