<?xml version="1.0" ?>
<!-- =================================================================================== -->
<!-- |    This document was autogenerated by xacro from sample.urdf.xacro              | -->
<!-- |    EDITING THIS FILE BY HAND IS NOT RECOMMENDED                                 | -->
<!-- =================================================================================== -->
<!-- top of urdf -->
<robot name="sample_robot" xmlns:xacro="http://ros.org/wiki/xacro">
  <!-- defined num and set of link and joint -->
  <!-- lowest level of xacro -->
  <!-- valiables to be used -->
  <material name="black">
    <color rgba="0.2 0.2 0.2 1.0"/>
  </material>
  <!-- FIXME add color -->
  <!-- link to provide the location reference for the arm -->
  <link name="base_link"/>
  <!-- 1. the first top link and joint -->
  <link name="sample_robot_mounting_link"/>
  <joint name="sample_robot_mounting_joint" type="fixed">
    <origin rpy="0 3.14159265359 0" xyz="0 0 0"/>
    <parent link="base_link"/>
    <child link="sample_robot_mounting_link"/>
  </joint>
  <joint name="bracket_0_1_joint" type="fixed">
    <origin rpy="0 0 0" xyz="0 0 0"/>
    <parent link="sample_robot_mounting_link"/>
    <child link="bracket_1_link"/>
  </joint>
  <link name="bracket_1_link">
    <visual>
      <origin rpy="0 0 0" xyz="0 0 0"/>
      <geometry>
        <mesh filename="package://my_robot_description/meshes/bracket_1.stl" scale="0.001 0.001 0.001"/>
      </geometry>
      <material name="black"/>
    </visual>
    <inertial>
      <mass value="1.702"/>
      <!-- kg Fe -->
      <origin rpy="0 0 0" xyz="0 0 0"/>
      <inertia ixx="3.186E+06" ixy="-3.570E-09" ixz="1.566E-04" iyy="3.186E+06" iyz="3.570E-10" izz="3.189E+06"/>
    </inertial>
    <collision>
      <origin rpy="0 0 0" xyz="0 0 0.0155"/>
      <geometry>
        <cylinder length="0.031" radius="0.0455"/>
      </geometry>
    </collision>
  </link>
  <!-- FIXME add llimit ulimit vlimit -->
  <joint name="bracket_1_2_joint" type="continuous">
    <origin rpy="0 0 0" xyz="0 0 0.051"/>
    <axis xyz="0 0 1"/>
    <parent link="bracket_1_link"/>
    <child link="bracket_2_link"/>
  </joint>
  <link name="bracket_2_link">
    <visual>
      <!-- FIXME change this to stl -->
      <origin rpy="0 0 0" xyz="0 0 0"/>
      <geometry>
        <mesh filename="package://my_robot_description/meshes/bracket_2.stl" scale="0.001 0.001 0.001"/>
      </geometry>
    </visual>
    <inertial>
      <origin rpy="0 0 0" xyz="0 0 0"/>
      <mass value="4.758"/>
      <!-- kg Fe -->
      <!-- TODO need to check -->
      <inertia ixx="3.161E+07" ixy="-0.012" ixz="0.022" iyy="3.000E+07" iyz="6.590E+06" izz="7.749E+06"/>
    </inertial>
    <collision>
      <origin rpy="0 0 0" xyz="0 0 0.08"/>
      <geometry>
        <cylinder length="0.160" radius="0.06025"/>
      </geometry>
    </collision>
  </link>
  <!-- FIXME add limit and ulimit vilimit -->
  <joint name="bracket_2_3_joint" type="continuous">
    <origin rpy="0 0 0" xyz="0 0 0.1125"/>
    <axis xyz="0 1 0"/>
    <parent link="bracket_2_link"/>
    <child link="bracket_3_link"/>
  </joint>
  <link name="bracket_3_link">
    <visual>
      <origin rpy="0 0 0" xyz="0 0 0"/>
      <geometry>
        <mesh filename="package://my_robot_description/meshes/bracket_3.stl" scale="0.001 0.001 0.001"/>
      </geometry>
      <material name="black"/>
    </visual>
    <inertial>
      <mass value="3.912"/>
      <!-- kg Fe TODO need to check -->
      <origin rpy="0 0 0" xyz="0 0 0"/>
      <inertia ixx="1.537E+07" ixy="0.012" ixz="0.003" iyy="1.386E+07" iyz="-3.777E+05" izz="5.691E+06"/>
    </inertial>
    <collision>
      <origin rpy="0 0 0" xyz="0 0 0.077"/>
      <geometry>
        <cylinder length="0.154" radius="0.056"/>
      </geometry>
    </collision>
  </link>
  <!-- add color and limis -->
  <joint name="bracket_3_4_joint" type="continuous">
    <origin rpy="0 0 0" xyz="0 0 0.1065"/>
    <axis xyz="0 0 1"/>
    <parent link="bracket_3_link"/>
    <child link="bracket_4_link"/>
  </joint>
  <link name="bracket_4_link">
    <visual>
      <origin rpy="0 0 0" xyz="0 0 0"/>
      <geometry>
        <mesh filename="package://my_robot_description/meshes/bracket_4.stl" scale="0.001 0.001 0.001"/>
      </geometry>
    </visual>
    <inertial>
      <mass value="3.912"/>
      <!-- kg Fe TODO need to check -->
      <origin rpy="0 0 0" xyz="0 0 0"/>
      <inertia ixx="2.648E+07" ixy="-0.012" ixz="0.021" iyy="2.487E+07" iyz="6.157E+06" izz="5.793E+06"/>
    </inertial>
    <collision>
      <origin rpy="0 0 0" xyz="0 0 0.0765"/>
      <geometry>
        <cylinder length="0.153" radius="0.056"/>
      </geometry>
    </collision>
  </link>
  <joint name="bracket_4_5_joint" type="continuous">
    <origin rpy="0 0 0" xyz="0 0 0.1055"/>
    <axis xyz="0 1 0"/>
    <parent link="bracket_4_link"/>
    <child link="bracket_5_link"/>
  </joint>
  <link name="bracket_5_link">
    <visual>
      <origin rpy="0 0 0" xyz="0 0 0"/>
      <geometry>
        <mesh filename="package://my_robot_description/meshes/bracket_5.stl" scale="0.001 0.001 0.001"/>
      </geometry>
      <material name="black"/>
    </visual>
    <inertial>
      <mass value="4.097"/>
      <!-- kg Fe TODO need to check -->
      <origin rpy="0 0 0" xyz="0 0 0"/>
      <inertia ixx="2.236E+07" ixy="-15.891" ixz="-14.923" iyy="2.049E+07" iyz="-3.746E+06" izz="5.810E+06"/>
    </inertial>
    <collision>
      <origin rpy="0 0 0" xyz="-0.032 0 0.096"/>
      <geometry>
        <box size="0.064 0.095 0.192"/>
      </geometry>
    </collision>
  </link>
  <joint name="bracket_5_6_joint" type="continuous">
    <origin rpy="0 0 0" xyz="0 0 0.098"/>
    <axis xyz="0 1 0"/>
    <parent link="bracket_5_link"/>
    <child link="bracket_6_link"/>
  </joint>
  <link name="bracket_6_link">
    <visual>
      <origin rpy="0 0 0" xyz="0 0 0"/>
      <geometry>
        <mesh filename="package://my_robot_description/meshes/bracket_6.stl" scale="0.001 0.001 0.001"/>
      </geometry>
    </visual>
    <inertial>
      <mass value="2.888"/>
      <!-- kg Fe TODO check this -->
      <origin rpy="0 0 0" xyz="0 0 0"/>
      <inertia ixx="1.130E+07" ixy="0.009" ixz="-0.002" iyy="1.076E+07" iyz="1.389E+05" izz="3.340E+06"/>
    </inertial>
    <collision>
      <origin rpy="0 0 0" xyz="0 0 0.069"/>
      <geometry>
        <cylinder length="0.138" radius="0.04875"/>
      </geometry>
    </collision>
  </link>
  <joint name="bracket_6_7_joint" type="continuous">
    <origin rpy="0 0 0" xyz="0 0 0.0915"/>
    <axis xyz="0 0 1"/>
    <parent link="bracket_6_link"/>
    <child link="bracket_7_link"/>
  </joint>
  <link name="bracket_7_link">
    <visual>
      <origin rpy="0 0 0" xyz="0 0 0"/>
      <!-- need to rotate model -->
      <geometry>
        <mesh filename="package://my_robot_description/meshes/bracket_7.stl" scale="0.001 0.001 0.001"/>
      </geometry>
      <material name="black"/>
    </visual>
    <inertial>
      <mass value="0.825"/>
      <!-- kg Fe TODO check this -->
      <origin rpy="0 0 0" xyz="0 0 0"/>
      <inertia ixx="7.480E+05" ixy="7.140E-10" ixz="9.655E-05" iyy="7.480E+05" iyz="0.00" izz="9.705E+05"/>
    </inertial>
    <collision>
      <origin rpy="0 0 0" xyz="0 0 0.0155"/>
      <geometry>
        <cylinder length="0.031" radius="0.0465"/>
      </geometry>
    </collision>
  </link>
  <joint name="bracket_7_end_effector_joint" type="fixed">
    <origin rpy="0 0 0" xyz="0 0 0.031"/>
    <parent link="bracket_7_link"/>
    <child link="end_effector_link"/>
  </joint>
  <link name="end_effector_link">
    <visual>
      <origin rpy="0 0 0" xyz="0 0 0"/>
      <geometry>
        <mesh filename="package://my_robot_description/meshes/mounting_hand.stl" scale="0.001 0.001 0.001"/>
      </geometry>
    </visual>
    <inertial>
      <mass value="0.733"/>
      <!-- kg Fe TODO check this -->
      <origin rpy="0 0 0" xyz="0 0 0"/>
      <inertia ixx="5.794E+05" ixy="-1825.742" ixz="5189.318" iyy="9.352E+05" iyz="2261.065" izz="7.247E+05"/>
    </inertial>
    <collision>
      <origin rpy="0 0 0" xyz="0.0475 0.027 0.02975"/>
      <geometry>
        <box size="0.095 0.054 0.0595"/>
      </geometry>
    </collision>
  </link>
</robot>

