<?xml version="1.0"?>
<robot xmlns:xacro="http://ros.org/wiki/xacro">
<!-- defined num and set of link and joint -->
<!-- lowest level of xacro -->

<!-- valiables to be used -->
   <material name="black">
      <color rgba="0.2 0.2 0.2 1.0" />
   </material>
<!--TODO add color --> 
<!-- sample_robot_foundation_1 -->
  <xacro:macro name="sample_robot_foundation_1" params="parent *origin">
    <joint name="base_link_foundation_1_joint" type="fixed">
      <xacro:insert_block name="origin" />
      <parent link="${parent}" />
      <child link="sample_robot_foundation_1_link" />
    </joint>
    <link name="sample_robot_foundation_1_link">
	<!-- pysical values of foundations are not fixed -->
     <visual>
        <origin xyz="0 0 0" rpy="0 0 0" />
        <geometry>
         <box size="0.004 0.120 0.7" />
        </geometry>
      </visual>

      <collision>
        <origin xyz="0 0 0" rpy="0 0 0" />
        <geometry>
         <box size="0.004 0.120 0.7" />
        </geometry>
      </collision>

      <inertial>
        <mass value="1.0" /> <!-- This is just temporary value -->
        <origin xyz="0 0 0" rpy="0 0 0" />
        <!-- <inertia ixx="${(0.7*0.7+0.12*0.12)/12}" ixy="0" ixz="0" iyy=" ${(0.004*0.004+0.7*0.7)/12}" iyz="0" izz="${(0.004*0.004+0.120*0.120)/12}"/> -->
	<inertia ixx="0.04203" ixy="0" ixz="0" iyy="0.04083467" iyz="0" izz="0.00120133" />
      </inertial>
    </link>
  
  </xacro:macro>
  <!-- sample_robot_foundation_2 -->
  <xacro:macro name="sample_robot_foundation_2" params="parent *origin">
    <joint name="foundation_1_2_joint" type="fixed">
      <xacro:insert_block name="origin" />
      <parent link="${parent}" />
      <child link="sample_robot_foundation_2_link" />
    </joint>
    <link name="sample_robot_foundation_2_link">
      <visual>
        <origin xyz="0 0 0" rpy="0 0 0" />
        <geometry>
          <box size="0.120 0.120 0.004" />
        </geometry>
      </visual>

      <collision>
        <origin xyz="0 0 0" rpy="0 0 0" />
        <geometry>
          <box size="0.120 0.120 0.004" />
        </geometry>
      </collision>

      <inertial>
        <mass value="1.0" /> <!-- This is just temporary value -->
        <origin xyz="0 0 0" rpy="0 0 0" />
	<!-- <inertia ixx="${(0.004*0.004+0.12*0.12)/12}" ixy="0" ixz="0" iyy=" ${(0.004*0.004+0.12*0.12)/12}" iyz="0" izz="${(0.120*0.12+0.120*0.12)/12}" /> -->
	<inertia ixx="0.00120133" ixy="0" ixz="0" iyy="0.00120133" iyz="0" izz="2.4E-3" />
      </inertial>
    </link>
  </xacro:macro>

<!-- bracket_1 -->
  <xacro:macro name="bracket_1" params="parent *origin">
    <joint name="bracket_0_1_joint" type="fixed">
      <xacro:insert_block name="origin" />
      <parent link="${parent}" />
      <child link="bracket_1_link" />
    </joint>
    <link name="bracket_1_link">
      <visual>
        <origin xyz="0 0 0" rpy="0 0 0" />
        <geometry>
          <mesh filename="package://my_robot_description/meshes/bracket_1.stl" scale="0.001 0.001 0.001"  />
        </geometry>
        <material name="black" />
      </visual>

      <inertial>
        <mass value="0.609588" /> <!-- kg Al 7505 -->
        <origin xyz="0 0 0" rpy="0 0 0" /> 
        <inertia ixx="1.140E+06" ixy="-1.278E-09" ixz="5.604E-05" iyy="1.140E+06" iyz="1.278E-10" izz="1.142E+06" />
      </inertial>
      
      <collision>
        <origin xyz="0 0 ${31/(2*1000)}" rpy="0 0 0" />
        <geometry>
          <cylinder radius="${45.5/1000}" length="${31/1000}" />
        </geometry>
      </collision>

    </link>
  </xacro:macro>

<!-- bracket_2 -->
  <xacro:macro name="bracket_2" params="parent *origin"> <!-- TODO add llimit ulimit vlimit -->
    <joint name="bracket_1_2_joint" type="continuous">
      <xacro:insert_block name="origin"/>
      <axis xyz="0 0 1" />
      <parent link="${parent}" />
      <child link="bracket_2_link"/>
    </joint>

    <link name="bracket_2_link">
      <visual>
        <origin xyz="0 0 0" rpy="0 0 0" />
        <geometry>
          <mesh filename="package://my_robot_description/meshes/bracket_2.stl" scale="0.001 0.001 0.001"  />
        </geometry>
      </visual>

      <inertial>
        <origin xyz="0 0 0" rpy="0 0 0" />
        <mass value="1.703374" /> <!-- kg Al --> 
        <inertia ixx="1.131E+07" ixy="-0.004" ixz="0.008" iyy="1.074E+07" iyz="2.359E+06" izz="2.774E+06" />
      </inertial>

      <collision>
        <origin xyz="0 0 ${0.160/2}" rpy="0 0 0" />
        <geometry>
          <cylinder radius="${0.1205/2}" length="0.160" />
        </geometry>
      </collision>

    </link>
  </xacro:macro>

<!-- bracket_3 -->
  <xacro:macro name="bracket_3" params="parent *origin">
    <!-- FIXME add limit and ulimit vilimit -->
    <joint name="bracket_2_3_joint" type="continuous">
      <xacro:insert_block name="origin" />
      <axis xyz="0 1 0" />
      <parent link="${parent}" />
      <child link="bracket_3_link" />
    </joint>

    <link name="bracket_3_link">
      <visual>
        <origin xyz="0 0 0" rpy="0 0 0" />
        <geometry>
          <mesh filename="package://my_robot_description/meshes/bracket_3.stl" scale="0.001 0.001 0.001"  />
        </geometry>
        <material name="black" />
      </visual>

      <inertial>
        <mass value="1.400547" /> <!-- kg Al -->
        <origin xyz="0 0 0" rpy="0 0 0" />
        <inertia ixx="5.501E+06" ixy="0.004" ixz="9.410E-04" iyy="4.963E+06" iyz="-1.352E+05" izz="2.037E+06" />
      </inertial>
      
      <collision>
        <origin xyz="0 0 ${0.154/2}" rpy="0 0 0" />
        <geometry>
          <cylinder radius="${0.112/2}" length="0.154" />
        </geometry>
      </collision>

    </link>
  </xacro:macro>
 
  <!-- bracket_4 -->
  <xacro:macro name="bracket_4" params="parent *origin">
    <!-- add color and limis -->
    <joint name="bracket_3_4_joint" type="continuous">
      <xacro:insert_block name="origin" />
      <axis xyz="0 0 1" />
      <parent link="${parent}" />
      <child link="bracket_4_link" />
    </joint>
    <link name="bracket_4_link">
      
      <visual>
        <origin xyz="0 0 0" rpy="0 0 0" />
        <geometry>
          <mesh filename="package://my_robot_description/meshes/bracket_4.stl" scale="0.001 0.001 0.001"  />
        </geometry>
      </visual>

      <inertial>
        <mass value="1.400547" /> <!-- kg Al -->
        <origin xyz="0 0 0" rpy="0 0 0" /> 
        <inertia ixx="9.477E+06" ixy="-0.004" ixz="0.008" iyy="8.903E+06" iyz="2.204E+06" izz="2.074E+06" />
      </inertial>

      <collision>
        <origin xyz="0 0 ${0.153/2}" rpy="0 0 0" />
        <geometry>
          <cylinder radius="${0.112/2}" length="0.153" />
        </geometry>
      </collision>


    </link>
  </xacro:macro>


  <!-- bracket_5 -->
  <xacro:macro name="bracket_5" params="parent *origin">
    <joint name="bracket_4_5_joint" type="continuous">
      <xacro:insert_block name="origin" />
      <axis xyz="0 1 0" />
      <parent link="${parent}" />
      <child link="bracket_5_link" />
    </joint>

    <link name="bracket_5_link">
      
      <visual>
        <origin xyz="0 0 0" rpy="0 0 0" />
        <geometry>
          <mesh filename="package://my_robot_description/meshes/bracket_5.stl" scale="0.001 0.001 0.001"  />
        </geometry>
        <material name="black" />
      </visual>

      <inertial>
        <mass value="1.466917" /> <!-- kg Al -->
        <origin xyz="0 0 0" rpy="0 0 0" /> 
        <inertia ixx="8.003E+06" ixy="-5.689" ixz="-5.342" iyy="7.336E+06" iyz="-1.341E+06" izz="2.080E+06" />
      </inertial>

      <collision>
        <origin xyz="${-1*0.064/2} 0 ${0.192/2}" rpy="0 0 0" />
        <geometry>
          <box size="0.064 0.095 0.192" />
        </geometry>
      </collision>


    </link>
  </xacro:macro>

  <!-- bracket_6 -->
  <xacro:macro name="bracket_6" params="parent *origin">
    <joint name="bracket_5_6_joint" type="continuous">
      <xacro:insert_block name="origin" />
      <axis xyz="0 1 0" />
      <parent link="${parent}"  />
      <child link="bracket_6_link" />
    </joint>

    <link name="bracket_6_link">
      <visual>
        <origin xyz="0 0 0" rpy="0 0 0" />
        <geometry>
          <mesh filename="package://my_robot_description/meshes/bracket_6.stl" scale="0.001 0.001 0.001"  />
        </geometry>
      </visual>

      <inertial>
        <mass value="1.033966" /> <!-- kg Fe TODO check this -->
        <origin xyz="0 0 0" rpy="0 0 0" />
        <inertia ixx="4.047E+06" ixy="0.003" ixz="-8.494E-04" iyy="3.853E+06" iyz="4.974E+04" izz="1.196E+06" />
      </inertial>

      <collision>
        <origin xyz="0 0 ${0.138/2}" rpy="0 0 0" />
        <geometry>
          <cylinder radius="${0.0975/2}" length="0.138" />
        </geometry>
      </collision>


    </link>
  </xacro:macro>

  <!-- bracket_7 -->
  <xacro:macro name="bracket_7" params="parent *origin">
    <joint name="bracket_6_7_joint" type="continuous">
      <xacro:insert_block name="origin"/>
      <axis xyz="0 0 1" />
      <parent link="${parent}" />
      <child link="bracket_7_link" />
    </joint> 

    <link name="bracket_7_link">
      <visual>
        <origin xyz="0 0 0" rpy="0 0 0" /> <!-- need to rotate model -->
        <geometry>
          <mesh filename="package://my_robot_description/meshes/bracket_7.stl" scale="0.001 0.001 0.001"  />
        </geometry>
        <material name="black" />
      </visual>

      <inertial>
        <mass value="0.29527" /> <!-- kg Fe TODO check this -->
        <origin xyz="0 0 0" rpy="0 0 0" />
        <inertia ixx="2.678E+05" ixy="2.556E-10" ixz="3.456E-05" iyy="2.678E+05" iyz="0.00" izz="3.474E+05" />
      </inertial>

      <collision>
        <origin xyz="0 0 ${0.031/2}" rpy="0 0 0" />
        <geometry>
          <cylinder radius="${0.0465}" length="0.031" />
        </geometry>
      </collision>
    </link>
  </xacro:macro>

  <!-- end effector -->
  <!-- TODO add real end effector later -->
  <xacro:macro name="end_effector" params="parent *origin">
    <joint name="bracket_7_end_effector_joint" type="fixed">
      <xacro:insert_block name="origin" />
      <parent link="${parent}" />
      <child link="end_effector_link" />
    </joint>

    <link name="end_effector_link">
      <visual>
        <origin xyz="0 0 0" rpy="0 0 0" />
        <geometry>
          <mesh filename="package://my_robot_description/meshes/mounting_hand.stl" scale="0.001 0.001 0.001" />
        </geometry>
      </visual>

      <inertial>
        <mass value="0.26231" /> <!-- kg Fe TODO check this -->
        <origin xyz="0 0 0" rpy="0 0 0" /> 
        <inertia ixx="2.074E+05" ixy="-653.546" ixz="1857.577" iyy="3.348E+05" iyz="809.375" izz="2.594E+05" />
      </inertial>

      <collision>
        <origin xyz="${0.095/2} ${0.054/2} ${0.0595/2}" rpy="0 0 0" />
        <geometry>
          <box size="0.095 0.054 0.0595" />
        </geometry>
      </collision>
    </link>

  </xacro:macro>

</robot>
