<?xml version="1.0" ?>
<!-- =================================================================================== -->
<!-- |    This document was autogenerated by xacro from simulated_my_robot.urdf.xacro  | -->
<!-- |    EDITING THIS FILE BY HAND IS NOT RECOMMENDED                                 | -->
<!-- =================================================================================== -->
<robot name="sample_robot" xmlns:xacro="http://ros.org/wiki/xacro">
  <!-- this xacro file is for parsing urdf file for simulating in gazebo -->
  <!-- defined num and set of link and joint -->
  <!-- lowest level of xacro -->
  <!-- valiables to be used -->
  <material name="black">
    <color rgba="0.2 0.2 0.2 1.0"/>
  </material>
  <!-- TODO create my_robot.gazebo: gazebo-customization elements, such as color -->
  <!-- TODO create my_robot_materials.xacro: for importing rviz colors -->
  <!-- TODO foundation is temporary added -->
  <!-- link to provide the location reference for the whole arm -->
  <link name="base_link"/>
  <joint name="base_link_foundation_1_joint" type="fixed">
    <origin rpy="0 0 0" xyz="0.502 0 -0.348"/>
    <parent link="sample_robot_foundation_2_link"/>
    <child link="sample_robot_foundation_1_link"/>
  </joint>
  <link name="sample_robot_foundation_1_link">
    <!-- pysical values of foundations are not fixed -->
    <visual>
      <origin rpy="0 0 0" xyz="0 0 0"/>
      <geometry>
        <box size="0.004 0.120 0.7"/>
      </geometry>
    </visual>
    <collision>
      <origin rpy="0 0 0" xyz="0 0 0"/>
      <geometry>
        <box size="0.004 0.120 0.7"/>
      </geometry>
    </collision>
    <inertial>
      <mass value="1.0"/>
      <!-- This is just temporary value -->
      <origin rpy="0 0 0" xyz="0 0 0"/>
      <!-- <inertia ixx="${(0.7*0.7+0.12*0.12)/12}" ixy="0" ixz="0" iyy=" ${(0.004*0.004+0.7*0.7)/12}" iyz="0" izz="${(0.004*0.004+0.120*0.120)/12}"/> -->
      <inertia ixx="0.04203" ixy="0" ixz="0" iyy="0.04083467" iyz="0" izz="0.00120133"/>
    </inertial>
  </link>
  <joint name="foundation_1_2_joint" type="fixed">
    <origin xyz="0 0 0"/>
    <parent link="base_link"/>
    <child link="sample_robot_foundation_2_link"/>
  </joint>
  <link name="sample_robot_foundation_2_link">
    <visual>
      <origin rpy="0 0 0" xyz="0 0 0"/>
      <geometry>
        <box size="1.0 0.120 0.004"/>
      </geometry>
    </visual>
    <collision>
      <origin rpy="0 0 0" xyz="0 0 0"/>
      <geometry>
        <box size="1.0 0.120 0.004"/>
      </geometry>
    </collision>
    <inertial>
      <mass value="1.0"/>
      <!-- This is just temporary value -->
      <origin rpy="0 0 0" xyz="0 0 0"/>
      <!-- <inertia ixx="${(0.004*0.004+0.12*0.12)/12}" ixy="0" ixz="0" iyy=" ${(0.004*0.004+0.24*0.24)/12}" iyz="0" izz="${(0.24*0.24+0.120*0.12)/12}" /> -->
      <inertia ixx="0.00120133" ixy="0" ixz="0" iyy="4.80133E-3" iyz="0" izz="6.0E-3"/>
    </inertial>
  </link>
  <!-- 1. the first top link and joint -->
  <link name="sample_robot_mounting_link"/>
  <joint name="sample_robot_mounting_joint" type="fixed">
    <origin rpy="0 3.14159265359 0" xyz="0 0 0"/>
    <parent link="base_link"/>
    <child link="sample_robot_mounting_link"/>
  </joint>
  <joint name="bracket_0_1_joint" type="fixed">
    <origin rpy="0 0 0" xyz="0 0 0"/>
    <parent link="sample_robot_mounting_link"/>
    <child link="bracket_1_link"/>
  </joint>
  <link name="bracket_1_link">
    <visual>
      <origin rpy="0 0 0" xyz="0 0 0"/>
      <geometry>
        <mesh filename="package://my_robot_description/meshes/bracket_1.stl" scale="0.001 0.001 0.001"/>
      </geometry>
      <material name="black"/>
    </visual>
    <inertial>
      <mass value="0.609588"/>
      <!-- kg Al 7505 -->
      <origin rpy="0 0 0" xyz="0 0 0"/>
      <inertia ixx="1.140E+06" ixy="-1.278E-09" ixz="5.604E-05" iyy="1.140E+06" iyz="1.278E-10" izz="1.142E+06"/>
    </inertial>
    <collision>
      <origin rpy="0 0 0" xyz="0 0 0.0155"/>
      <geometry>
        <cylinder length="0.031" radius="0.0455"/>
      </geometry>
    </collision>
  </link>
  <!-- TODO add llimit ulimit vlimit -->
  <joint name="bracket_1_2_joint" type="continuous">
    <origin rpy="0 0 0" xyz="0 0 0.051"/>
    <axis xyz="0 0 1"/>
    <parent link="bracket_1_link"/>
    <child link="bracket_2_link"/>
  </joint>
  <link name="bracket_2_link">
    <visual>
      <origin rpy="0 0 0" xyz="0 0 0"/>
      <geometry>
        <mesh filename="package://my_robot_description/meshes/bracket_2.stl" scale="0.001 0.001 0.001"/>
      </geometry>
    </visual>
    <inertial>
      <origin rpy="0 0 0" xyz="0 0 0"/>
      <mass value="1.703374"/>
      <!-- kg Al -->
      <inertia ixx="1.131E+07" ixy="-0.004" ixz="0.008" iyy="1.074E+07" iyz="2.359E+06" izz="2.774E+06"/>
    </inertial>
    <collision>
      <origin rpy="0 0 0" xyz="0 0 0.08"/>
      <geometry>
        <cylinder length="0.160" radius="0.06025"/>
      </geometry>
    </collision>
  </link>
  <!-- FIXME add limit and ulimit vilimit -->
  <joint name="bracket_2_3_joint" type="continuous">
    <origin rpy="0 0 0" xyz="0 0 0.1125"/>
    <axis xyz="0 1 0"/>
    <parent link="bracket_2_link"/>
    <child link="bracket_3_link"/>
  </joint>
  <link name="bracket_3_link">
    <visual>
      <origin rpy="0 0 0" xyz="0 0 0"/>
      <geometry>
        <mesh filename="package://my_robot_description/meshes/bracket_3.stl" scale="0.001 0.001 0.001"/>
      </geometry>
      <material name="black"/>
    </visual>
    <inertial>
      <mass value="1.400547"/>
      <!-- kg Al -->
      <origin rpy="0 0 0" xyz="0 0 0"/>
      <inertia ixx="5.501E+06" ixy="0.004" ixz="9.410E-04" iyy="4.963E+06" iyz="-1.352E+05" izz="2.037E+06"/>
    </inertial>
    <collision>
      <origin rpy="0 0 0" xyz="0 0 0.077"/>
      <geometry>
        <cylinder length="0.154" radius="0.056"/>
      </geometry>
    </collision>
  </link>
  <!-- add color and limis -->
  <joint name="bracket_3_4_joint" type="continuous">
    <origin rpy="0 0 0" xyz="0 0 0.1065"/>
    <axis xyz="0 0 1"/>
    <parent link="bracket_3_link"/>
    <child link="bracket_4_link"/>
  </joint>
  <link name="bracket_4_link">
    <visual>
      <origin rpy="0 0 0" xyz="0 0 0"/>
      <geometry>
        <mesh filename="package://my_robot_description/meshes/bracket_4.stl" scale="0.001 0.001 0.001"/>
      </geometry>
    </visual>
    <inertial>
      <mass value="1.400547"/>
      <!-- kg Al -->
      <origin rpy="0 0 0" xyz="0 0 0"/>
      <inertia ixx="9.477E+06" ixy="-0.004" ixz="0.008" iyy="8.903E+06" iyz="2.204E+06" izz="2.074E+06"/>
    </inertial>
    <collision>
      <origin rpy="0 0 0" xyz="0 0 0.0765"/>
      <geometry>
        <cylinder length="0.153" radius="0.056"/>
      </geometry>
    </collision>
  </link>
  <joint name="bracket_4_5_joint" type="continuous">
    <origin rpy="0 0 0" xyz="0 0 0.1055"/>
    <axis xyz="0 1 0"/>
    <parent link="bracket_4_link"/>
    <child link="bracket_5_link"/>
  </joint>
  <link name="bracket_5_link">
    <visual>
      <origin rpy="0 0 0" xyz="0 0 0"/>
      <geometry>
        <mesh filename="package://my_robot_description/meshes/bracket_5.stl" scale="0.001 0.001 0.001"/>
      </geometry>
      <material name="black"/>
    </visual>
    <inertial>
      <mass value="1.466917"/>
      <!-- kg Al -->
      <origin rpy="0 0 0" xyz="0 0 0"/>
      <inertia ixx="8.003E+06" ixy="-5.689" ixz="-5.342" iyy="7.336E+06" iyz="-1.341E+06" izz="2.080E+06"/>
    </inertial>
    <collision>
      <origin rpy="0 0 0" xyz="-0.032 0 0.096"/>
      <geometry>
        <box size="0.064 0.095 0.192"/>
      </geometry>
    </collision>
  </link>
  <joint name="bracket_5_6_joint" type="continuous">
    <origin rpy="0 0 0" xyz="0 0 0.098"/>
    <axis xyz="0 1 0"/>
    <parent link="bracket_5_link"/>
    <child link="bracket_6_link"/>
  </joint>
  <link name="bracket_6_link">
    <visual>
      <origin rpy="0 0 0" xyz="0 0 0"/>
      <geometry>
        <mesh filename="package://my_robot_description/meshes/bracket_6.stl" scale="0.001 0.001 0.001"/>
      </geometry>
    </visual>
    <inertial>
      <mass value="1.033966"/>
      <!-- kg Fe TODO check this -->
      <origin rpy="0 0 0" xyz="0 0 0"/>
      <inertia ixx="4.047E+06" ixy="0.003" ixz="-8.494E-04" iyy="3.853E+06" iyz="4.974E+04" izz="1.196E+06"/>
    </inertial>
    <collision>
      <origin rpy="0 0 0" xyz="0 0 0.069"/>
      <geometry>
        <cylinder length="0.138" radius="0.04875"/>
      </geometry>
    </collision>
  </link>
  <joint name="bracket_6_7_joint" type="continuous">
    <origin rpy="0 0 0" xyz="0 0 0.0915"/>
    <axis xyz="0 0 1"/>
    <parent link="bracket_6_link"/>
    <child link="bracket_7_link"/>
  </joint>
  <link name="bracket_7_link">
    <visual>
      <origin rpy="0 0 0" xyz="0 0 0"/>
      <!-- need to rotate model -->
      <geometry>
        <mesh filename="package://my_robot_description/meshes/bracket_7.stl" scale="0.001 0.001 0.001"/>
      </geometry>
      <material name="black"/>
    </visual>
    <inertial>
      <mass value="0.29527"/>
      <!-- kg Fe TODO check this -->
      <origin rpy="0 0 0" xyz="0 0 0"/>
      <inertia ixx="2.678E+05" ixy="2.556E-10" ixz="3.456E-05" iyy="2.678E+05" iyz="0.00" izz="3.474E+05"/>
    </inertial>
    <collision>
      <origin rpy="0 0 0" xyz="0 0 0.0155"/>
      <geometry>
        <cylinder length="0.031" radius="0.0465"/>
      </geometry>
    </collision>
  </link>
  <joint name="bracket_7_end_effector_joint" type="fixed">
    <origin rpy="0 0 0" xyz="0 0 0.031"/>
    <parent link="bracket_7_link"/>
    <child link="end_effector_link"/>
  </joint>
  <link name="end_effector_link">
    <visual>
      <origin rpy="0 0 0" xyz="0 0 0"/>
      <geometry>
        <mesh filename="package://my_robot_description/meshes/mounting_hand.stl" scale="0.001 0.001 0.001"/>
      </geometry>
    </visual>
    <inertial>
      <mass value="0.26231"/>
      <!-- kg Fe TODO check this -->
      <origin rpy="0 0 0" xyz="0 0 0"/>
      <inertia ixx="2.074E+05" ixy="-653.546" ixz="1857.577" iyy="3.348E+05" iyz="809.375" izz="2.594E+05"/>
    </inertial>
    <collision>
      <origin rpy="0 0 0" xyz="0.0475 0.027 0.02975"/>
      <geometry>
        <box size="0.095 0.054 0.0595"/>
      </geometry>
    </collision>
  </link>
  <!-- Add the transmission necessary to move the simulated robot's joints -->
  <!-- TODO check the type of transmission, hardwareInterface and so on -->
  <!-- First revolute servo -->
  <transmission name="bracket_1_2_revolute">
    <type>transmission_interface/SimpleTransimission</type>
    <joint name="bracket_1_2_joint">
      <hardwareInterface>hardware_interface/PositionJointInterface</hardwareInterface>
    </joint>
    <actuator name="bracket_1_2_revolute_servo">
      <hardwareInterface>PositionJointInterface</hardwareInterface>
      <mechanicalReduction>1</mechanicalReduction>
    </actuator>
  </transmission>
  <!-- Second revolute servo -->
  <transmission name="bracket_2_3_revolute">
    <type>transmission_interface/SimpleTransmission</type>
    <joint name="bracket_2_3_joint">
      <hardwareInterface>hardware_interface/PositionJointInterface</hardwareInterface>
    </joint>
    <actuator name="bracket_2_3_revolute_servo">
      <hardwareInterface>PositionJointInterface</hardwareInterface>
      <mechanicalReduction>1</mechanicalReduction>
    </actuator>
  </transmission>
  <!-- 3. revolute servo -->
  <transmission name="bracket_3_4_revolute">
    <type>transmission_interface/SimpleTransmission</type>
    <joint name="bracket_3_4_joint">
      <hardwareInterface>hardware_interface/PositionJointInterface</hardwareInterface>
    </joint>
    <actuator name="bracket_3_4_revolute_servo">
      <hardwareInterface>PositionJointInterface</hardwareInterface>
      <mechanicalReduction>1</mechanicalReduction>
    </actuator>
  </transmission>
  <!-- 4. revolute servo -->
  <transmission name="bracket_4_5_revolute">
    <type>transmission_interface/SimpleTransmission</type>
    <joint name="bracket_4_5_joint">
      <hardwareInterface>hardware_interface/PositionJointInterface</hardwareInterface>
    </joint>
    <actuator name="bracket_4_5_revolute_servo">
      <hardwareInterface>PositionJointInterface</hardwareInterface>
      <mechanicalReduction>1</mechanicalReduction>
    </actuator>
  </transmission>
  <!-- 5. revolute servo -->
  <transmission name="bracket_5_6_revolute">
    <type>transmission_interface/SimpleTransmission</type>
    <joint name="bracket_5_6_joint">
      <hardwareInterface>hardware_interface/PositionJointInterface</hardwareInterface>
    </joint>
    <actuator name="bracket_5_6_revolute_servo">
      <hardwareInterface>PositionJointInterface</hardwareInterface>
      <mechanicalReduction>1</mechanicalReduction>
    </actuator>
  </transmission>
  <!-- 6. revolute servo -->
  <transmission name="bracket_6_7_revolute">
    <type>transmission_interface/SimpleTransmission</type>
    <joint name="bracket_6_7_joint">
      <hardwareInterface>hardware_interface/PositionJointInterface</hardwareInterface>
    </joint>
    <actuator name="bracket_6_7_revolute_servo">
      <hardwareInterface>PositionJointInterface</hardwareInterface>
      <mechanicalReduction>1</mechanicalReduction>
    </actuator>
  </transmission>
  <!-- add the gazebo_ros_control plugin -->
  <!-- this is needed for parsing the transmission tag and loads the appropriate hardware interfaces and controler manager -->
  <!-- TODO need to check this is correct way to install gazebo plugins -->
  <!-- plug in for whole robot -->
  <gazebo>
    <!-- plugin for add ros_control -->
    <plugin filename="libgazebo_ros_control.so" name="control"/>
    <!-- add ros_joint_state_publisher -->
    <plugin filename="libgazebo_ros_joint_state_publisher.so" name="joint_state_publisher">
      <jointName>
        bracket_1_2_joint,
        bracket_2_3_joint,
        bracket_3_4_joint,
        bracket_4_5_joint,
        bracket_5_6_joint,
        bracket_6_7_joint
      </jointName>
    </plugin>
  </gazebo>
  <!-- Add sensors for joints -->
  <gazebo reference="bracket_1_2_joint">
    <sensor name="force_torque" type="force_torque">
      <update_rate>100</update_rate>
      <visualize>true</visualize>
      <always_on>true</always_on>
    </sensor>
  </gazebo>
  <gazebo reference="bracket_1_2_joint">
    <sensor name="force_torque" type="force_torque">
      <update_rate>100</update_rate>
      <visualize>true</visualize>
      <always_on>true</always_on>
    </sensor>
  </gazebo>
  <gazebo reference="bracket_2_3_joint">
    <sensor name="force_torque" type="force_torque">
      <update_rate>100</update_rate>
      <visualize>true</visualize>
      <always_on>true</always_on>
    </sensor>
  </gazebo>
  <gazebo reference="bracket_3_4_joint">
    <sensor name="force_torque" type="force_torque">
      <update_rate>100</update_rate>
      <visualize>true</visualize>
      <always_on>true</always_on>
    </sensor>
  </gazebo>
  <gazebo reference="bracket_4_5_joint">
    <sensor name="force_torque" type="force_torque">
      <update_rate>100</update_rate>
      <visualize>true</visualize>
      <always_on>true</always_on>
    </sensor>
  </gazebo>
  <gazebo reference="bracket_5_6_joint">
    <sensor name="force_torque" type="force_torque">
      <update_rate>100</update_rate>
      <visualize>true</visualize>
      <always_on>true</always_on>
    </sensor>
  </gazebo>
  <gazebo reference="bracket_6_7_joint">
    <sensor name="force_torque" type="force_torque">
      <update_rate>100</update_rate>
      <visualize>true</visualize>
      <always_on>true</always_on>
    </sensor>
  </gazebo>
</robot>

